<?xml version="1.0" ?>
<!-- =================================================================================== -->
<!-- |    This document was autogenerated by xacro from robot_model.xacro              | -->
<!-- |    EDITING THIS FILE BY HAND IS NOT RECOMMENDED                                 | -->
<!-- =================================================================================== -->
<robot name="myrobot">
  <!--materials-->
  <material name="blue">
    <color rgba="0 0 0.8 1"/>
  </material>
  <material name="black">
    <color rgba="0 0 0 1"/>
  </material>
  <material name="white">
    <color rgba="1 1 1 1"/>
  </material>
  <material name="red">
    <color rgba="0.8 0.0 0.0 1.0"/>
  </material>
  <!--world link-->
  <link name="world"/>
  <!--base link-->
  <link name="link_base">
    <visual>
      <origin xyz="0.0 0.0 0.15"/>
      <geometry>
        <box size="0.07 0.07 0.3"/>
      </geometry>
      <material name="blue"/>
    </visual>
    <collision>
      <origin xyz="0.0 0.0 0.15"/>
      <geometry>
        <box size="0.07 0.07 0.3"/>
      </geometry>
    </collision>
    <inertial>
      <mass value="1"/>
      <inertia ixx="1.0" ixy="0.0" ixz="0.0" iyy="1.0" iyz="0.0" izz="1.0"/>
    </inertial>
  </link>
  <gazebo reference="link_base">
    <mu1>0.2</mu1>
    <mu2>0.2</mu2>
    <material>Gazebo/Blue</material>
  </gazebo>
  <!--second link z-axis rotate-->
  <link name="link_1">
    <visual>
      <origin xyz="0.0 0.0 0.15"/>
      <geometry>
        <box size="0.07 0.07 0.3"/>
      </geometry>
      <material name="white"/>
    </visual>
    <collision>
      <origin xyz="0.0 0.0 0.15"/>
      <geometry>
        <box size="0.07 0.07 0.3"/>
      </geometry>
    </collision>
    <inertial>
      <mass value="1"/>
      <inertia ixx="1.0" ixy="0.0" ixz="0.0" iyy="1.0" iyz="0.0" izz="1.0"/>
    </inertial>
  </link>
  <gazebo reference="link_1">
    <mu1>0.2</mu1>
    <mu2>0.2</mu2>
    <material>Gazebo/White</material>
  </gazebo>
  <!--3th link z-axis rotate-->
  <link name="link_2">
    <visual>
      <origin xyz="0.0 0.0 0.35"/>
      <geometry>
        <box size="0.07 0.07 0.8"/>
      </geometry>
      <material name="blue"/>
    </visual>
    <collision>
      <origin xyz="0.0 0.0 0.35"/>
      <geometry>
        <box size="0.07 0.07 0.8"/>
      </geometry>
    </collision>
    <inertial>
      <mass value="2"/>
      <inertia ixx="1.0" ixy="0.0" ixz="0.0" iyy="1.0" iyz="0.0" izz="1.0"/>
    </inertial>
  </link>
  <gazebo reference="link_2">
    <mu1>0.2</mu1>
    <mu2>0.2</mu2>
    <material>Gazebo/Blue</material>
  </gazebo>
  <!--4th link z-axis rotate-->
  <link name="link_3">
    <visual>
      <origin xyz="0.0 0.0 0.20"/>
      <geometry>
        <box size="0.07 0.07 0.5"/>
      </geometry>
      <material name="white"/>
    </visual>
    <collision>
      <origin xyz="0.0 0.0 0.20"/>
      <geometry>
        <box size="0.07 0.07 0.5"/>
      </geometry>
    </collision>
    <inertial>
      <mass value="1.5"/>
      <inertia ixx="1.0" ixy="0.0" ixz="0.0" iyy="1.0" iyz="0.0" izz="1.0"/>
    </inertial>
  </link>
  <gazebo reference="link_3">
    <mu1>0.2</mu1>
    <mu2>0.2</mu2>
    <material>Gazebo/White</material>
  </gazebo>
  <!--5th link z-axis rotate-->
  <link name="link_4">
    <visual>
      <origin xyz="0.0 0.0 0.1"/>
      <geometry>
        <box size="0.07 0.07 0.2"/>
      </geometry>
      <material name="blue"/>
    </visual>
    <collision>
      <origin xyz="0.0 0.0 0.1"/>
      <geometry>
        <box size="0.07 0.07 0.2"/>
      </geometry>
    </collision>
    <inertial>
      <mass value="0.7"/>
      <inertia ixx="1.0" ixy="0.0" ixz="0.0" iyy="1.0" iyz="0.0" izz="1.0"/>
    </inertial>
  </link>
  <gazebo reference="link_4">
    <mu1>0.2</mu1>
    <mu2>0.2</mu2>
    <material>Gazebo/Blue</material>
  </gazebo>
  <!--gripper link-->
  <link name="link_gripper">
    <visual>
      <origin xyz="0.0 0.0 0.05"/>
      <geometry>
        <box size="0.07 0.07 0.2"/>
      </geometry>
      <material name="white"/>
    </visual>
    <collision>
      <origin xyz="0.0 0.0 0.05"/>
      <geometry>
        <box size="0.07 0.07 0.2"/>
      </geometry>
    </collision>
    <inertial>
      <mass value="0.2"/>
      <inertia ixx="1.0" ixy="0.0" ixz="0.0" iyy="1.0" iyz="0.0" izz="1.0"/>
    </inertial>
  </link>
  <gazebo reference="link_gripper">
    <mu1>0.2</mu1>
    <mu2>0.2</mu2>
    <material>Gazebo/White</material>
  </gazebo>
  <!--CameraHolder link-->
  <link name="link_cameraHolder">
    <visual>
      <origin xyz="0.0 0.0 0.0"/>
      <geometry>
        <box size="0.07 0.07 0.05"/>
      </geometry>
      <material name="white"/>
    </visual>
    <collision>
      <origin xyz="0.0 0.0 0.0"/>
      <geometry>
        <box size="0.07 0.07 0.05"/>
      </geometry>
    </collision>
    <inertial>
      <mass value="0.2"/>
      <inertia ixx="1.0" ixy="0.0" ixz="0.0" iyy="1.0" iyz="0.0" izz="1.0"/>
    </inertial>
  </link>
  <gazebo reference="link_cameraHolder">
    <mu1>0.2</mu1>
    <mu2>0.2</mu2>
    <material>Gazebo/White</material>
  </gazebo>
  <!--camera link -->
  <link name="link_camera">
    <visual>
      <origin xyz="0.0 0.0 0.0"/>
      <geometry>
        <box size="0.02 0.07 0.04"/>
      </geometry>
      <material name="red"/>
    </visual>
    <collision>
      <origin xyz="0.0 0.0 0.0"/>
      <geometry>
        <box size="0.02 0.07 0.04"/>
      </geometry>
    </collision>
    <inertial>
      <mass value="0.1"/>
      <inertia ixx="1.0" ixy="0.0" ixz="0.0" iyy="1.0" iyz="0.0" izz="1.0"/>
    </inertial>
  </link>
  <gazebo reference="link_camera">
    <material>Gazebo/Red</material>
  </gazebo>
  <!--vacuum link -->
  <link name="link_vacuum">
    <visual>
      <origin rpy="0.0 1.5707963267948966 0.0" xyz="-0.05 0.0 0.0"/>
      <geometry>
        <cylinder length="0.1" radius="0.01"/>
      </geometry>
      <material name="black"/>
    </visual>
    <collision>
      <origin rpy="0.0 1.5707963267948966 0.0" xyz="-0.05 0.0 0.0"/>
      <geometry>
        <cylinder length="0.1" radius="0.01"/>
      </geometry>
    </collision>
    <inertial>
      <mass value="0.1"/>
      <inertia ixx="1.0" ixy="0.0" ixz="0.0" iyy="1.0" iyz="0.0" izz="1.0"/>
    </inertial>
  </link>
  <gazebo reference="link_vacuum">
    <mu1>0.2</mu1>
    <mu2>0.2</mu2>
    <material>Gazebo/Black</material>
  </gazebo>
  <!--joint of world and link_base-->
  <joint name="joint_world_base" type="fixed">
    <origin rpy="0 0 0" xyz="0 0 0"/>
    <parent link="world"/>
    <child link="link_base"/>
  </joint>
  <!--joint of link_base and link_1-->
  <joint name="joint_base_1" type="revolute">
    <parent link="link_base"/>
    <child link="link_1"/>
    <origin xyz="0.0 0.0 0.3"/>
    <axis xyz="0 0 1"/>
    <limit effort="1000.0" lower="-2.5" upper="2.5" velocity="5.0"/>
    <dynamics damping="0.7" friction="0.7"/>
  </joint>
  <!--joint of link_1 and link_2-->
  <joint name="joint_1_2" type="revolute">
    <parent link="link_1"/>
    <child link="link_2"/>
    <origin xyz="0.0 0.07 0.25"/>
    <axis xyz="0 1 0"/>
    <limit effort="1000.0" lower="-2.0" upper="2.0" velocity="5.0"/>
    <dynamics damping="0.7" friction="0.7"/>
  </joint>
  <!--joint of link_2 and link_3-->
  <joint name="joint_2_3" type="revolute">
    <parent link="link_2"/>
    <child link="link_3"/>
    <origin xyz="0.0 -0.07 0.7"/>
    <axis xyz="0 1 0"/>
    <limit effort="1000.0" lower="-2.0" upper="2.0" velocity="5.0"/>
    <dynamics damping="0.7" friction="0.7"/>
  </joint>
  <!--joint of link_3 and link_4-->
  <joint name="joint_3_4" type="revolute">
    <parent link="link_3"/>
    <child link="link_4"/>
    <origin xyz="0.0 0.0 0.45"/>
    <axis xyz="0 0 1"/>
    <limit effort="1000.0" lower="-2.5" upper="2.5" velocity="5.0"/>
    <dynamics damping="0.7" friction="0.7"/>
  </joint>
  <!--joint of link_4 and link_gripper-->
  <joint name="joint_4_gripper" type="revolute">
    <parent link="link_4"/>
    <child link="link_gripper"/>
    <origin xyz="0.0 0.07 0.15"/>
    <axis xyz="0 1 0"/>
    <limit effort="1000.0" lower="-2.0" upper="2.0" velocity="5.0"/>
    <dynamics damping="0.7" friction="0.7"/>
  </joint>
  <!--joint of link_gripper and link_cameraHolder-->
  <joint name="joint_gripper_cameraHolder" type="fixed">
    <origin rpy="0 0 0" xyz="-0.07 0 0.125"/>
    <parent link="link_gripper"/>
    <child link="link_cameraHolder"/>
  </joint>
  <!--joint of link_cameraHolder and link_camera-->
  <joint name="joint_cameraHolder_camera" type="fixed">
    <parent link="link_cameraHolder"/>
    <child link="link_camera"/>
    <origin rpy="0.0 -1.5707963267948966 0.0" xyz="-0.015 0.0 0.035"/>
  </joint>
  <!--joint of link_gripper and link_vacuum-->
  <joint name="joint_gripper_vacuum" type="revolute">
    <parent link="link_gripper"/>
    <child link="link_vacuum"/>
    <origin rpy="0.0 -1.5707963267948966 0.0" xyz="0.0 0.0 0.25"/>
    <axis xyz="1 0 0"/>
    <limit effort="1000.0" lower="-2.0" upper="2.0" velocity="5.0"/>
    <dynamics damping="0.7" friction="0.7"/>
  </joint>
  <!--ros2_control module-->
  <ros2_control name="GazeboSystem" type="system">
    <hardware>
      <plugin>gazebo_ros2_control/GazeboSystem</plugin>
    </hardware>
    <joint name="joint_base_1">
      <command_interface name="position">
        <param name="min">-2.5</param>
        <param name="max">2.5</param>
      </command_interface>
      <state_interface name="position"/>
      <state_interface name="velocity"/>
      <state_interface name="effort"/>
    </joint>
    <joint name="joint_1_2">
      <command_interface name="position">
        <param name="min">-2.0</param>
        <param name="max">2.0</param>
      </command_interface>
      <state_interface name="position"/>
      <state_interface name="velocity"/>
      <state_interface name="effort"/>
    </joint>
    <joint name="joint_2_3">
      <command_interface name="position">
        <param name="min">-2.0</param>
        <param name="max">2.0</param>
      </command_interface>
      <state_interface name="position"/>
      <state_interface name="velocity"/>
      <state_interface name="effort"/>
    </joint>
    <joint name="joint_3_4">
      <command_interface name="position">
        <param name="min">-2.5</param>
        <param name="max">2.5</param>
      </command_interface>
      <state_interface name="position"/>
      <state_interface name="velocity"/>
      <state_interface name="effort"/>
    </joint>
    <joint name="joint_4_gripper">
      <command_interface name="position">
        <param name="min">-2.0</param>
        <param name="max">2.0</param>
      </command_interface>
      <state_interface name="position"/>
      <state_interface name="velocity"/>
      <state_interface name="effort"/>
    </joint>
    <joint name="joint_gripper_vacuum">
      <command_interface name="position">
        <param name="min">-2.0</param>
        <param name="max">2.0</param>
      </command_interface>
      <state_interface name="position"/>
      <state_interface name="velocity"/>
      <state_interface name="effort"/>
    </joint>
  </ros2_control>
  <!--gazebo plugins-->
  <!--plugin for ros2 control-->
  <gazebo>
    <plugin filename="libgazebo_ros2_control.so" name="gazebo_ros2_control">
      <parameters>/home/jan/ws_myrobot/install/myrobot/share/myrobot/model/myrobot_ros2_controllers.yaml</parameters>
      <!-- <robotNamespace>/myrobot</robotNamespace> -->
    </plugin>
  </gazebo>
  <!--plugin for camera-->
  <gazebo reference="link_camera">
    <!-- <gazebo>
    <link name= "link_camera"> -->
    <sensor name="sensor_name" type="multicamera">
      <camera name="left">
        <horizontal_fov>1.3962634</horizontal_fov>
        <image>
          <width>800</width>
          <height>800</height>
          <format>R8G8B8</format>
        </image>
        <clip>
          <near>0.02</near>
          <far>300</far>
        </clip>
        <noise>
          <type>gaussian</type>
          <mean>0.0</mean>
          <stddev>0.007</stddev>
        </noise>
      </camera>
      <camera name="right">
        <pose>0 -0.07 0 0 0 0</pose>
        <horizontal_fov>1.3962634</horizontal_fov>
        <image>
          <width>800</width>
          <height>800</height>
          <format>R8G8B8</format>
        </image>
        <clip>
          <near>0.02</near>
          <far>300</far>
        </clip>
        <noise>
          <type>gaussian</type>
          <mean>0.0</mean>
          <stddev>0.007</stddev>
        </noise>
      </camera>
      <!-- Set update_rate only sensor, not on plugin -->
      <update_rate>1</update_rate>
      <plugin filename="libgazebo_ros_camera.so" name="plugin_name">
        <ros>
          <namespace>custom_ns</namespace>
          <!-- topics need to be prefixed with camera_name for remapping -->
          <argument>custom_camera/left/image_raw:=custom_camera/left/custom_image</argument>
          <argument>custom_camera/right/image_raw:=custom_camera/right/custom_image</argument>
          <argument>custom_camera/left/camera_info:=custom_camera/left/custom_camera_info</argument>
          <argument>custom_camera/right/camera_info:=custom_camera/right/custom_camera_info</argument>
        </ros>
        <camera_name>custom_camera</camera_name>
        <frameName>left_camera_optical_frame</frameName>
      </plugin>
    </sensor>
  </gazebo>
  <gazebo>
    <plugin filename="libgazebo_ros_vacuum_gripper.so" name="vacuum_gripper">
      <ros>
        <namespace>/robot_model</namespace>
      </ros>
      <link_name>link_vacuum</link_name>
      <maxDistance>0.05</maxDistance>
    </plugin>
  </gazebo>
</robot>
