<?xml version="1.0"?>
<robot name="myrobot" xmlns:xacro="http://ros.org/wiki/xacro">
  <xacro:property name="width" value='0.07'/>
  <!--materials-->
  <material name="blue">
    <color rgba="0 0 0.8 1"/>
  </material>

  <material name="black">
    <color rgba="0 0 0 1"/>
  </material>

  <material name="white">
    <color rgba="1 1 1 1"/>
  </material>

  <material name="red">
    <color rgba="0.8 0.0 0.0 1.0"/>
  </material>
  <!--inertia macro-->
  <!-- <xacro:macro name="default_inertial" params="mass w h">
    <inertial>
      <origin xyz="0 0 ${h/2}" rpy="0 0 0"/>
      <mass value="${mass}"/>
      <inertia
        ixx="${mass / 12.0 * (w*w + h*h)}" ixy="0.0" ixz="0.0"
        iyy="${mass / 12.0 * (h*h + w*w)}" iyz="0.0"
        izz="${mass / 12.0 * (w*w + w*w)}"/>
    </inertial>
  </xacro:macro> -->
  <xacro:macro name="default_inertial" params="mass w h">
    <inertial>
      <mass value="${mass}" />
      <inertia ixx="1.0" ixy="0.0" ixz="0.0" iyy="1.0" iyz="0.0" izz="1.0" />
    </inertial>
  </xacro:macro>
<!--world link-->
  <link name="world"/>
<!--base link-->
  <link name="link_base">
    <visual>
        <origin xyz="0.0 0.0 0.15"/>
        <geometry>
            <box size= "${width} ${width} 0.3"/>
        </geometry>
        <material name="blue"/>
    </visual>
    <collision>
        <origin xyz="0.0 0.0 0.15"/>
        <geometry>
            <box size= "${width} ${width} 0.3"/>
        </geometry>      
    </collision>
    <xacro:default_inertial mass="1" w="${width}" h="0.3"/>
  </link>
  <gazebo reference= "link_base">
      <mu1>0.2</mu1>
      <mu2>0.2</mu2>
      <material>Gazebo/Blue</material>
  </gazebo>
<!--second link z-axis rotate-->

    <link name="link_1">
        <visual>
            <origin xyz="0.0 0.0 0.15"/>
            <geometry>
                <box size="${width} ${width} 0.3"/>
            </geometry>
            <material name="white"/>
        </visual>
        <collision>
            <origin xyz="0.0 0.0 0.15"/>
            <geometry>
                <box size="${width} ${width} 0.3"/>
            </geometry>
        </collision>
        <xacro:default_inertial mass="1" w="${width}" h="0.3"/>
    </link>
    <gazebo reference= "link_1">
      <mu1>0.2</mu1>
      <mu2>0.2</mu2>
      <material>Gazebo/White</material>
    </gazebo>

<!--3th link z-axis rotate-->

    <link name="link_2">
        <visual>
            <origin xyz="0.0 0.0 0.35"/>
            <geometry>
                <box size="${width} ${width} 0.8"/>
            </geometry>
            <material name="blue"/>
        </visual>
        <collision>
            <origin xyz="0.0 0.0 0.35"/>
            <geometry>
                <box size="${width} ${width} 0.8"/>
            </geometry>
        </collision>
        <xacro:default_inertial mass="2" w="${width}" h="0.8"/>
    </link>
    <gazebo reference= "link_2">
      <mu1>0.2</mu1>
      <mu2>0.2</mu2>
      <material>Gazebo/Blue</material>
    </gazebo>

<!--4th link z-axis rotate-->

    <link name="link_3">
        <visual>
            <origin xyz="0.0 0.0 0.20"/>
            <geometry>
                <box size="${width} ${width} 0.5"/>
            </geometry>
            <material name="white"/>
        </visual>
        <collision>
            <origin xyz="0.0 0.0 0.20"/>
            <geometry>
                <box size="${width} ${width} 0.5"/>
            </geometry>
        </collision>
        <xacro:default_inertial mass="1.5" w="${width}" h="0.5"/>
    </link>
    <gazebo reference= "link_3">
      <mu1>0.2</mu1>
      <mu2>0.2</mu2>
      <material>Gazebo/White</material>
    </gazebo>

<!--5th link z-axis rotate-->

    <link name="link_4">
        <visual>
            <origin xyz="0.0 0.0 0.1"/>
            <geometry>
                <box size="${width} ${width} 0.2"/>
            </geometry>
            <material name="blue"/>
        </visual>
        <collision>
            <origin xyz="0.0 0.0 0.1"/>
            <geometry>
                <box size="${width} ${width} 0.2"/>
            </geometry>
        </collision>
        <xacro:default_inertial mass="0.7" w="${width}" h="0.2"/>
    </link>
    <gazebo reference= "link_4">
      <mu1>0.2</mu1>
      <mu2>0.2</mu2>
      <material>Gazebo/Blue</material>
    </gazebo>

<!--gripper link-->

    <link name="link_gripper">
        <visual>
            <origin xyz="0.0 0.0 0.05"/>
            <geometry>
                <box size="${width} ${width} 0.2"/>
            </geometry>
            <material name="white"/>
        </visual>
        <collision>
            <origin xyz="0.0 0.0 0.05"/>
            <geometry>
                <box size="${width} ${width} 0.2"/>
            </geometry>
        </collision>
        <xacro:default_inertial mass="0.2" w="${width}" h="0.2"/>
    </link>
    <gazebo reference= "link_gripper">
      <mu1>0.2</mu1>
      <mu2>0.2</mu2>
      <material>Gazebo/White</material>
    </gazebo>

<!--CameraHolder link-->

    <link name="link_cameraHolder">
        <visual>
            <origin xyz="0.0 0.0 0.0"/>
            <geometry>
                <box size="${width} ${width} 0.05"/>
            </geometry>
            <material name="white"/>
        </visual>
        <collision>
            <origin xyz="0.0 0.0 0.0"/>
            <geometry>
                <box size="${width} ${width} 0.05"/>
            </geometry>
        </collision>
        <xacro:default_inertial mass="0.2" w="${width}" h="0.05"/>
    </link>
    <gazebo reference= "link_cameraHolder">
      <mu1>0.2</mu1>
      <mu2>0.2</mu2>
      <material>Gazebo/White</material>
    </gazebo>

<!--camera link -->

    <link name="link_camera">
        <visual>
            <origin xyz="0.0 0.0 0.0"/>
            <geometry>
                <box size="0.02 0.07 0.04"/>
            </geometry>
            <material name="red"/>
        </visual>
        <collision>
            <origin xyz="0.0 0.0 0.0"/>
            <geometry>
                <box size="0.02 0.07 0.04"/>
            </geometry>
        </collision>
        <xacro:default_inertial mass="0.1" w="0.04" h="0.02"/>
    </link>
    <gazebo reference= "link_camera">
      <material>Gazebo/Red</material>
    </gazebo>

<!--vacuum link -->

    <link name="link_vacuum">
        <visual>
            <origin xyz="-0.05 0.0 0.0" rpy="0.0 ${pi/2} 0.0"/>
            <geometry>
                <cylinder length="0.1" radius="0.01"/>
            </geometry>
            <material name="black"/>
        </visual>
        <collision>
            <origin xyz="-0.05 0.0 0.0" rpy="0.0 ${pi/2} 0.0"/>
            <geometry>
                <cylinder length="0.1" radius="0.01"/>
            </geometry>
        </collision>
        <xacro:default_inertial mass="0.1" w="0.01" h="0.1"/>
    </link>
    <gazebo reference= "link_vacuum">
      <mu1>0.2</mu1>
      <mu2>0.2</mu2>
      <material>Gazebo/Black</material>
    </gazebo>

    <!--joint of world and link_base-->
    <joint name="joint_world_base" type="fixed">
      <origin xyz="0 0 0" rpy="0 0 0"/>
      <parent link="world"/>
      <child link="link_base"/>
    </joint>

    <!--joint of link_base and link_1-->
    <joint name="joint_base_1" type="revolute">
        <parent link="link_base"/>
        <child link="link_1"/>
        <origin xyz="0.0 0.0 0.3"/>
        <axis xyz="0 0 1"/>
        <limit effort="1000.0" upper="2.5" lower="-2.5" velocity="5.0"/>
        <dynamics damping="0.7" friction="0.7"/>
    </joint>

    <!--joint of link_1 and link_2-->
    <joint name="joint_1_2" type="revolute">
        <parent link="link_1"/>
        <child link="link_2"/>
        <origin xyz="0.0 ${width} 0.25"/>
        <axis xyz="0 1 0"/>
        <limit effort="1000.0" upper="2.0" lower="-2.0" velocity="5.0"/>
        <dynamics damping="0.7" friction="0.7"/>
    </joint>

    <!--joint of link_2 and link_3-->
    <joint name="joint_2_3" type="revolute">
        <parent link="link_2"/>
        <child link="link_3"/>
        <origin xyz="0.0 -${width} 0.7"/>
        <axis xyz="0 1 0"/>
        <limit effort="1000.0" upper="2.0" lower="-2.0" velocity="5.0"/>
        <dynamics damping="0.7" friction="0.7"/>
    </joint>

    <!--joint of link_3 and link_4-->
    <joint name="joint_3_4" type="revolute">
        <parent link="link_3"/>
        <child link="link_4"/>
        <origin xyz="0.0 0.0 0.45"/>
        <axis xyz="0 0 1"/>
        <limit effort="1000.0" upper="2.5" lower="-2.5" velocity="5.0"/>
        <dynamics damping="0.7" friction="0.7"/>
    </joint>

    <!--joint of link_4 and link_gripper-->
    <joint name="joint_4_gripper" type="revolute">
        <parent link="link_4"/>
        <child link="link_gripper"/>
        <origin xyz="0.0 ${width} 0.15"/>
        <axis xyz="0 1 0"/>
        <limit effort="1000.0" upper="2.0" lower="-2.0" velocity="5.0"/>
        <dynamics damping="0.7" friction="0.7"/>
    </joint>

    <!--joint of link_gripper and link_cameraHolder-->
    <joint name="joint_gripper_cameraHolder" type="fixed">
      <origin xyz="-${width} 0 0.125" rpy="0 0 0"/>
      <parent link="link_gripper"/>
      <child link="link_cameraHolder"/>
    </joint>

    <!--joint of link_cameraHolder and link_camera-->
    <joint name="joint_cameraHolder_camera" type="revolute">
        <parent link="link_cameraHolder"/>
        <child link="link_camera"/>
        <origin xyz="-0.015 0.0 0.035" rpy="0.0 ${-pi/2} 0.0"/>
        <!-- added for revolute joint type -->
        <axis xyz="1 0 0"/>
        <limit effort="1000.0" upper="0.0" lower="0.0" velocity="0.0"/>
        <dynamics damping="100.0" friction="100.0"/>
    </joint>

    <!--joint of link_gripper and link_vacuum-->
    <joint name="joint_gripper_vacuum" type="revolute">
        <parent link="link_gripper"/>
        <child link="link_vacuum"/>
        <origin xyz="0.0 0.0 0.25" rpy="0.0 ${-pi/2} 0.0"/>
        <axis xyz="1 0 0"/>
        <limit effort="1000.0" upper="2.0" lower="-2.0" velocity="5.0"/>
        <dynamics damping="0.7" friction="0.7"/>
    </joint>
    
  
    
    <!--ros2_control module-->
    <ros2_control name="GazeboSystem" type="system">
      <hardware>
        <plugin>gazebo_ros2_control/GazeboSystem</plugin>
      </hardware>

      <joint name="joint_base_1">
        <command_interface name="position">
          <param name="min">-2.5</param>
          <param name="max">2.5</param>
        </command_interface>
        <state_interface name="position"/>
        <state_interface name="velocity"/>
        <state_interface name="effort"/>
      </joint>

      <joint name="joint_1_2">
        <command_interface name="position">
          <param name="min">-2.0</param>
          <param name="max">2.0</param>
        </command_interface>
        <state_interface name="position"/>
        <state_interface name="velocity"/>
        <state_interface name="effort"/>
      </joint>

      <joint name="joint_2_3">
        <command_interface name="position">
          <param name="min">-2.0</param>
          <param name="max">2.0</param>
        </command_interface>
        <state_interface name="position"/>
        <state_interface name="velocity"/>
        <state_interface name="effort"/>
      </joint>

      <joint name="joint_3_4">
        <command_interface name="position">
          <param name="min">-2.5</param>
          <param name="max">2.5</param>
        </command_interface>
        <state_interface name="position"/>
        <state_interface name="velocity"/>
        <state_interface name="effort"/>
      </joint>

      <joint name="joint_4_gripper">
        <command_interface name="position">
          <param name="min">-2.0</param>
          <param name="max">2.0</param>
        </command_interface>
        <state_interface name="position"/>
        <state_interface name="velocity"/>
        <state_interface name="effort"/>
      </joint>

      <joint name="joint_gripper_vacuum">
        <command_interface name="position">
          <param name="min">-2.0</param>
          <param name="max">2.0</param>
        </command_interface>
        <state_interface name="position"/>
        <state_interface name="velocity"/>
        <state_interface name="effort"/>
      </joint>

      <!-- added for camera revolute joint type -->
      <joint name="joint_cameraHolder_camera">
        <command_interface name="position">
          <param name="min">-0.0</param>
          <param name="max">0.0</param>
        </command_interface>
        <state_interface name="position"/>
        <state_interface name="velocity"/>
        <state_interface name="effort"/>
      </joint>

    </ros2_control>

    <!--gazebo plugins-->
    <!--plugin for ros2 control-->
    <gazebo>
      <plugin name="gazebo_ros2_control" filename="libgazebo_ros2_control.so">
        <parameters>$(find myrobot)/model/myrobot_ros2_controllers.yaml</parameters>
        <!-- <robotNamespace>/myrobot</robotNamespace> -->
      </plugin>
    </gazebo>

    <!--plugin for camera-->
    <gazebo reference="link_camera">
    <!-- <gazebo>
    <link name= "link_camera"> -->
    <sensor type="multicamera" name="sensor_name">
          <camera name="left">
            <horizontal_fov>1.3962634</horizontal_fov>
            <image>
              <width>800</width>
              <height>800</height>
              <format>R8G8B8</format>
            </image>
            <clip>
              <near>0.02</near>
              <far>300</far>
            </clip>
            <noise>
              <type>gaussian</type>
              <mean>0.0</mean>
              <stddev>0.007</stddev>
            </noise>
          </camera>
          <camera name="right">
            <pose>0 -0.07 0 0 0 0</pose>
            <horizontal_fov>1.3962634</horizontal_fov>
            <image>
              <width>800</width>
              <height>800</height>
              <format>R8G8B8</format>
            </image>
            <clip>
              <near>0.02</near>
              <far>300</far>
            </clip>
            <noise>
              <type>gaussian</type>
              <mean>0.0</mean>
              <stddev>0.007</stddev>
            </noise>
          </camera>

          <!-- Set update_rate only sensor, not on plugin -->
          <update_rate>1</update_rate>

          <plugin name="cameras" filename="libgazebo_ros_camera.so">
            
            <ros>
              <namespace>/robot_model</namespace>
              <!-- topics need to be prefixed with camera_name for remapping -->
              <argument>custom_camera/left/image_raw:=camera/left/image</argument>
              <argument>custom_camera/right/image_raw:=camera/right/image</argument>
              <argument>custom_camera/left/camera_info:=camera/left/camera_info</argument>
              <argument>custom_camera/right/camera_info:=camera/right/camera_info</argument>
            </ros>

            <camera_name>stereocamera</camera_name>

            <frameName>left_camera_optical_frame</frameName>
          </plugin>
        </sensor>
    </gazebo>

  <!-- vacuum gripper plugins -->
  <gazebo>
    <plugin  name='vacuum_gripper1' filename='libgazebo_ros_vacuum_gripper.so'>
      <ros>
        <namespace>/robot_model1</namespace>
      </ros>
      <link_name>link_vacuum</link_name>
      <max_distance>0.5</max_distance>
      <fixed>ground_plane</fixed>
    </plugin>
  </gazebo>
  <!-- <gazebo>
    <plugin  name='vacuum_gripper2' filename='libgazebo_ros_vacuum_gripper.so'>
      <ros>
        <namespace>/robot_model2</namespace>
      </ros>
      <link_name>link_vacuum</link_name>
      <maxDistance>0.1</maxDistance>
      <minDistance>0.01</minDistance>
      <maxForce>50</maxForce>
    </plugin>
  </gazebo>
  <gazebo>
    <plugin  name='vacuum_gripper3' filename='libgazebo_ros_vacuum_gripper.so'>
      <ros>
        <namespace>/robot_model3</namespace>
      </ros>
      <link_name>link_vacuum</link_name>
      <maxDistance>0.1</maxDistance>
      <minDistance>0.01</minDistance>
      <maxForce>50</maxForce>
    </plugin>
  </gazebo>
  <gazebo>
    <plugin  name='vacuum_gripper4' filename='libgazebo_ros_vacuum_gripper.so'>
      <ros>
        <namespace>/robot_model4</namespace>
      </ros>
      <link_name>link_vacuum</link_name>
      <maxDistance>0.1</maxDistance>
      <minDistance>0.01</minDistance>
      <maxForce>50</maxForce>
    </plugin>
  </gazebo>
  <gazebo>
    <plugin  name='vacuum_gripper5' filename='libgazebo_ros_vacuum_gripper.so'>
      <ros>
        <namespace>/robot_model5</namespace>
      </ros>
      <link_name>link_vacuum</link_name>
      <maxDistance>0.1</maxDistance>
      <minDistance>0.01</minDistance>
      <maxForce>50</maxForce>
    </plugin>
  </gazebo>
  <gazebo>
    <plugin  name='vacuum_gripper6' filename='libgazebo_ros_vacuum_gripper.so'>
      <ros>
        <namespace>/robot_model6</namespace>
      </ros>
      <link_name>link_vacuum</link_name>
      <maxDistance>0.1</maxDistance>
      <minDistance>0.01</minDistance>
      <maxForce>50</maxForce>
    </plugin>
  </gazebo>
  <gazebo>
    <plugin  name='vacuum_gripper7' filename='libgazebo_ros_vacuum_gripper.so'>
      <ros>
        <namespace>/robot_model7</namespace>
      </ros>
      <link_name>link_vacuum</link_name>
      <maxDistance>0.1</maxDistance>
      <minDistance>0.01</minDistance>
      <maxForce>50</maxForce>
    </plugin>
  </gazebo>
  <gazebo>
    <plugin  name='vacuum_gripper8' filename='libgazebo_ros_vacuum_gripper.so'>
      <ros>
        <namespace>/robot_model8</namespace>
      </ros>
      <link_name>link_vacuum</link_name>
      <maxDistance>0.1</maxDistance>
      <minDistance>0.01</minDistance>
      <maxForce>50</maxForce>
    </plugin>
  </gazebo>
  <gazebo>
    <plugin  name='vacuum_gripper9' filename='libgazebo_ros_vacuum_gripper.so'>
      <ros>
        <namespace>/robot_model9</namespace>
      </ros>
      <link_name>link_vacuum</link_name>
      <maxDistance>0.1</maxDistance>
      <minDistance>0.01</minDistance>
      <maxForce>50</maxForce>
    </plugin>
  </gazebo>
  <gazebo>
    <plugin  name='vacuum_gripper10' filename='libgazebo_ros_vacuum_gripper.so'>
      <ros>
        <namespace>/robot_model10</namespace>
      </ros>
      <link_name>link_vacuum</link_name>
      <maxDistance>0.1</maxDistance>
      <minDistance>0.01</minDistance>
      <maxForce>50</maxForce>
    </plugin>
  </gazebo> -->
    
</robot>
